<?xml version="1.0" encoding="utf-8"?>
<!-- =================================================================================== -->
<!-- |    This document was autogenerated by xacro from humanoid.xacro                 | -->
<!-- |    EDITING THIS FILE BY HAND IS NOT RECOMMENDED                                 | -->
<!-- =================================================================================== -->
<robot name="dumpUrdf">
  <material name="orange">
    <color rgba="1.0 0.423529411765 0.0392156862745 1.0"/>
  </material>
  <link name="base_link">
	</link>
  <link name="base">
	</link>
  <joint name="base_base_link_rotation" type="fixed">
    <parent link="base_link"/>
    <child link="base"/>
    <origin rpy="1.57079632679 0 0" xyz="0 0 0"/>
  </joint>
  <link name="root">
    <inertial>
      <origin rpy="0 0 0" xyz="0.0 0.07 0.0"/>
      <mass value="6.000000"/>
      <inertia ixx="0.019440000000000002" ixy="0" ixz="0" iyy="0.019440000000000002" iyz="0" izz="0.019440000000000002"/>
    </inertial>
    <collision>
      <origin rpy="0 0 0" xyz="0.000000 0.070000 0.000000"/>
      <geometry>
        <sphere radius="0.09"/>
      </geometry>
    </collision>
    <visual>
      <origin rpy="0 0 0" xyz="0.000000 0.070000 0.000000"/>
      <geometry>
        <sphere radius="0.09"/>
      </geometry>
    </visual>
  </link>
  <joint name="root" type="fixed">
    <parent link="base"/>
    <child link="root"/>
    <origin rpy="0 0 0" xyz="0 0.000000 0.000000"/>
  </joint>
  <link name="chest">
    <inertial>
      <origin rpy="0 0 0" xyz="0.000000 0.120000 0.000000"/>
      <mass value="14.000000"/>
      <inertia ixx="0.06776000000000001" ixy="0" ixz="0" iyy="0.06776000000000001" iyz="0" izz="0.06776000000000001"/>
    </inertial>
    <collision>
      <origin rpy="0 0 0" xyz="0.000000 0.120000 0.000000"/>
      <geometry>
        <sphere radius="0.11"/>
      </geometry>
    </collision>
    <visual>
      <origin rpy="0 0 0" xyz="0.000000 0.120000 0.000000"/>
      <geometry>
        <sphere radius="0.11"/>
      </geometry>
    </visual>
  </link>
  <link name="root_chest_link1">
    <inertial>
      <mass value="1e-02"/>
      <inertia ixx="1e-02" ixy="0" ixz="0" iyy="1e-02" iyz="0" izz="1e-02"/>
    </inertial>
  </link>
  <joint name="root_chest_joint1" type="revolute">
    <origin rpy="0 0 0" xyz="0.000000 0.236151 0.000000"/>
    <parent link="root"/>
    <child link="root_chest_link1"/>
    <axis xyz="1 0 0"/>
    <limit effort="200" lower="-1.2" upper="1.2" velocity="3"/>
  </joint>
  <link name="root_chest_link2">
    <inertial>
      <mass value="1e-02"/>
      <inertia ixx="1e-02" ixy="0" ixz="0" iyy="1e-02" iyz="0" izz="1e-02"/>
    </inertial>
    <visual>
      <geometry>
        <sphere radius="0.05"/>
      </geometry>
      <material name="orange"/>
    </visual>
  </link>
  <joint name="root_chest_joint2" type="revolute">
    <parent link="root_chest_link1"/>
    <child link="root_chest_link2"/>
    <axis xyz="0 1 0"/>
    <limit effort="200" lower="-1.2" upper="1.2" velocity="3"/>
  </joint>
  <joint name="root_chest_joint3" type="revolute">
    <parent link="root_chest_link2"/>
    <child link="chest"/>
    <axis xyz="0 0 1"/>
    <limit effort="200" lower="-1.2" upper="1.2" velocity="3"/>
  </joint>
  <link name="neck">
    <inertial>
      <origin rpy="0 0 0" xyz="0.0 0.175 0.0"/>
      <mass value="2.000000"/>
      <inertia ixx="0.008405" ixy="0" ixz="0" iyy="0.008405" iyz="0" izz="0.008405"/>
    </inertial>
    <collision>
      <origin rpy="0 0 0" xyz="0.0 0.175 0.0"/>
      <geometry>
        <sphere radius="0.1025"/>
      </geometry>
    </collision>
    <visual>
      <origin rpy="0 0 0" xyz="0.0 0.175 0.0"/>
      <geometry>
        <sphere radius="0.1025"/>
      </geometry>
    </visual>
  </link>
  <link name="chest_neck_link1">
    <inertial>
      <mass value="1e-02"/>
      <inertia ixx="1e-02" ixy="0" ixz="0" iyy="1e-02" iyz="0" izz="1e-02"/>
    </inertial>
  </link>
  <joint name="chest_neck_joint1" type="revolute">
    <origin rpy="0 0 0" xyz="0.000000 0.223894 0.000000"/>
    <parent link="chest"/>
    <child link="chest_neck_link1"/>
    <axis xyz="1 0 0"/>
    <limit effort="50" lower="-1" upper="1" velocity="3"/>
  </joint>
  <link name="chest_neck_link2">
    <inertial>
      <mass value="1e-02"/>
      <inertia ixx="1e-02" ixy="0" ixz="0" iyy="1e-02" iyz="0" izz="1e-02"/>
    </inertial>
    <visual>
      <geometry>
        <sphere radius="0.05"/>
      </geometry>
      <material name="orange"/>
    </visual>
  </link>
  <joint name="chest_neck_joint2" type="revolute">
    <parent link="chest_neck_link1"/>
    <child link="chest_neck_link2"/>
    <axis xyz="0 1 0"/>
    <limit effort="50" lower="-1" upper="1" velocity="3"/>
  </joint>
  <joint name="chest_neck_joint3" type="revolute">
    <parent link="chest_neck_link2"/>
    <child link="neck"/>
    <axis xyz="0 0 1"/>
    <limit effort="50" lower="-1" upper="1" velocity="3"/>
  </joint>
  <link name="right_hip">
    <inertial>
      <origin rpy="0 0 0" xyz="0.000000 -0.210000 0.000000"/>
      <mass value="4.500000"/>
      <inertia ixx="0.037153124999999995" ixy="0.0" ixz="0.0" iyy="0.037153124999999995" iyz="0.0" izz="0.00680625"/>
    </inertial>
    <collision>
      <origin rpy="1.57079632679 0 0" xyz="0.000000 -0.210000 0.000000"/>
      <geometry>
        <cylinder length="0.225" radius="0.0275"/>
      </geometry>
    </collision>
    <visual>
      <origin rpy="1.57079632679 0 0" xyz="0.000000 -0.210000 0.000000"/>
      <geometry>
        <cylinder length="0.3" radius="0.055"/>
      </geometry>
    </visual>
  </link>
  <link name="root_right_hip_link1">
    <inertial>
      <mass value="1e-02"/>
      <inertia ixx="1e-02" ixy="0" ixz="0" iyy="1e-02" iyz="0" izz="1e-02"/>
    </inertial>
  </link>
  <joint name="root_right_hip_joint1" type="revolute">
    <origin rpy="0 0 0" xyz="0.000000 0.000000 0.084887"/>
    <parent link="root"/>
    <child link="root_right_hip_link1"/>
    <axis xyz="1 0 0"/>
    <limit effort="200" lower="-1.5" upper="1.5" velocity="3"/>
  </joint>
  <link name="root_right_hip_link2">
    <inertial>
      <mass value="1e-02"/>
      <inertia ixx="1e-02" ixy="0" ixz="0" iyy="1e-02" iyz="0" izz="1e-02"/>
    </inertial>
    <visual>
      <geometry>
        <sphere radius="0.05"/>
      </geometry>
      <material name="orange"/>
    </visual>
  </link>
  <joint name="root_right_hip_joint2" type="revolute">
    <parent link="root_right_hip_link1"/>
    <child link="root_right_hip_link2"/>
    <axis xyz="0 1 0"/>
    <limit effort="200" lower="-1.5" upper="1.5" velocity="3"/>
  </joint>
  <joint name="root_right_hip_joint3" type="revolute">
    <parent link="root_right_hip_link2"/>
    <child link="right_hip"/>
    <axis xyz="0 0 1"/>
    <limit effort="200" lower="-1.5" upper="1.5" velocity="3"/>
  </joint>
  <link name="right_knee">
    <inertial>
      <origin rpy="0 0 0" xyz="0.000000 -0.200000 0.000000"/>
      <mass value="3.000000"/>
      <inertia ixx="0.1" ixy="0" ixz="0" iyy="0.1" iyz="0" izz="0.1"/>
    </inertial>
    <collision>
      <origin rpy="1.57079632679 0 0" xyz="0.000000 -0.200000 0.000000"/>
      <geometry>
        <cylinder length="0.2325" radius="0.025"/>
      </geometry>
    </collision>
    <visual>
      <origin rpy="1.57079632679 0 0" xyz="0.000000 -0.200000 0.000000"/>
      <geometry>
        <cylinder length="0.31" radius="0.05"/>
      </geometry>
    </visual>
  </link>
  <joint name="right_knee" type="revolute">
    <parent link="right_hip"/>
    <child link="right_knee"/>
    <limit effort="150.0" lower="-3.14" upper="0." velocity="0.5"/>
    <origin rpy="0 0 0" xyz="0.000000 -0.421546 0.000000"/>
    <axis xyz="0.000000 0.000000 1.000000"/>
  </joint>
  <link name="right_ankle">
    <inertial>
      <origin rpy="0 0 0" xyz="0.045 -0.00225 0.000000"/>
      <mass value="1.000000"/>
      <inertia ixx="0.0009270833333333333" ixy="0.0" ixz="0.0" iyy="0.0028628333333333327" iyz="0.0" izz="0.003285749999999999"/>
    </inertial>
    <collision>
      <origin rpy="0 0 0" xyz="0.045 -0.00225 0.000000"/>
      <geometry>
        <box size="0.177 0.055 0.09"/>
      </geometry>
    </collision>
    <visual>
      <origin rpy="0 0 0" xyz="0.045 -0.00225 0.000000"/>
      <geometry>
        <box size="0.177 0.055 0.09"/>
      </geometry>
    </visual>
  </link>
  <link name="right_knee_right_ankle_link1">
    <inertial>
      <mass value="1e-02"/>
      <inertia ixx="1e-02" ixy="0" ixz="0" iyy="1e-02" iyz="0" izz="1e-02"/>
    </inertial>
  </link>
  <joint name="right_knee_right_ankle_joint1" type="revolute">
    <origin rpy="0 0 0" xyz="0.000000 -0.409870 0.000000"/>
    <parent link="right_knee"/>
    <child link="right_knee_right_ankle_link1"/>
    <axis xyz="1 0 0"/>
    <limit effort="90" lower="-1.2" upper="1.2" velocity="3"/>
  </joint>
  <link name="right_knee_right_ankle_link2">
    <inertial>
      <mass value="1e-02"/>
      <inertia ixx="1e-02" ixy="0" ixz="0" iyy="1e-02" iyz="0" izz="1e-02"/>
    </inertial>
    <visual>
      <geometry>
        <sphere radius="0.05"/>
      </geometry>
      <material name="orange"/>
    </visual>
  </link>
  <joint name="right_knee_right_ankle_joint2" type="revolute">
    <parent link="right_knee_right_ankle_link1"/>
    <child link="right_knee_right_ankle_link2"/>
    <axis xyz="0 1 0"/>
    <limit effort="90" lower="-1.2" upper="1.2" velocity="3"/>
  </joint>
  <joint name="right_knee_right_ankle_joint3" type="revolute">
    <parent link="right_knee_right_ankle_link2"/>
    <child link="right_ankle"/>
    <axis xyz="0 0 1"/>
    <limit effort="90" lower="-1.2" upper="1.2" velocity="3"/>
  </joint>
  <link name="right_shoulder">
    <inertial>
      <origin rpy="0 0 0" xyz="0.000000 -0.140000 0.000000"/>
      <mass value="1.500000"/>
      <inertia ixx="0.004809374999999999" ixy="0.0" ixz="0.0" iyy="0.004809374999999999" iyz="0.0" izz="0.0015187500000000001"/>
    </inertial>
    <collision>
      <origin rpy="1.57079632679 0 0" xyz="0.000000 -0.140000 0.000000"/>
      <geometry>
        <cylinder length="0.135" radius="0.0225"/>
      </geometry>
    </collision>
    <visual>
      <origin rpy="1.57079632679 0 0" xyz="0.000000 -0.140000 0.000000"/>
      <geometry>
        <cylinder length="0.18" radius="0.045"/>
      </geometry>
    </visual>
  </link>
  <link name="chest_right_shoulder_link1">
    <inertial>
      <mass value="1e-02"/>
      <inertia ixx="1e-02" ixy="0" ixz="0" iyy="1e-02" iyz="0" izz="1e-02"/>
    </inertial>
  </link>
  <joint name="chest_right_shoulder_joint1" type="revolute">
    <origin rpy="0 0 0" xyz="-0.02406 0.24350 0.18311"/>
    <parent link="chest"/>
    <child link="chest_right_shoulder_link1"/>
    <axis xyz="1 0 0"/>
    <limit effort="100" lower="-3.14" upper="3.14" velocity="3"/>
  </joint>
  <link name="chest_right_shoulder_link2">
    <inertial>
      <mass value="1e-02"/>
      <inertia ixx="1e-02" ixy="0" ixz="0" iyy="1e-02" iyz="0" izz="1e-02"/>
    </inertial>
    <visual>
      <geometry>
        <sphere radius="0.05"/>
      </geometry>
      <material name="orange"/>
    </visual>
  </link>
  <joint name="chest_right_shoulder_joint2" type="revolute">
    <parent link="chest_right_shoulder_link1"/>
    <child link="chest_right_shoulder_link2"/>
    <axis xyz="0 1 0"/>
    <limit effort="100" lower="-3.14" upper="3.14" velocity="3"/>
  </joint>
  <joint name="chest_right_shoulder_joint3" type="revolute">
    <parent link="chest_right_shoulder_link2"/>
    <child link="right_shoulder"/>
    <axis xyz="0 0 1"/>
    <limit effort="100" lower="-3.14" upper="3.14" velocity="3"/>
  </joint>
  <link name="right_elbow">
    <inertial>
      <origin rpy="0 0 0" xyz="0.000000 -0.120000 0.000000"/>
      <mass value="1.000000"/>
      <inertia ixx="0.0019187499999999999" ixy="0.0" ixz="0.0" iyy="0.0019187499999999999" iyz="0.0" izz="0.0008"/>
    </inertial>
    <collision>
      <origin rpy="1.57079632679 0 0" xyz="0.0 -0.12 0.0"/>
      <geometry>
        <cylinder length="0.10125" radius="0.02"/>
      </geometry>
    </collision>
    <visual>
      <origin rpy="1.57079632679 0 0" xyz="0.0 -0.12 0.0"/>
      <geometry>
        <cylinder length="0.135" radius="0.04"/>
      </geometry>
    </visual>
  </link>
  <joint name="right_elbow" type="revolute">
    <parent link="right_shoulder"/>
    <child link="right_elbow"/>
    <limit effort="60.0" lower="0" upper="3.14" velocity="0.5"/>
    <origin rpy="0 0 0" xyz="0.000000 -0.274788 0.000000"/>
    <axis xyz="0.000000 0.000000 1.000000"/>
  </joint>
  <link name="right_wrist">
    <inertial>
      <origin rpy="0 0 0" xyz="0.000000 0.000000 0.000000"/>
      <mass value="0.500000"/>
      <inertia ixx="0.00032" ixy="0" ixz="0" iyy="0.00032" iyz="0" izz="0.00032"/>
    </inertial>
    <collision>
      <origin rpy="0 0 0" xyz="0.000000 0.000000 0.000000"/>
      <geometry>
        <sphere radius="0.04"/>
      </geometry>
    </collision>
    <visual>
      <origin rpy="0 0 0" xyz="0.000000 0.000000 0.000000"/>
      <geometry>
        <sphere radius="0.04"/>
      </geometry>
    </visual>
  </link>
  <joint name="right_wrist" type="fixed">
    <parent link="right_elbow"/>
    <child link="right_wrist"/>
    <origin rpy="0 0 0" xyz="0.000000 -0.258947 0.000000"/>
  </joint>
  <link name="left_hip">
    <inertial>
      <origin rpy="0 0 0" xyz="0.000000 -0.210000 0.000000"/>
      <mass value="4.500000"/>
      <inertia ixx="0.037153124999999995" ixy="0.0" ixz="0.0" iyy="0.037153124999999995" iyz="0.0" izz="0.00680625"/>
    </inertial>
    <collision>
      <origin rpy="1.57079632679 0 0" xyz="0.000000 -0.210000 0.000000"/>
      <geometry>
        <cylinder length="0.225" radius="0.0275"/>
      </geometry>
    </collision>
    <visual>
      <origin rpy="1.57079632679 0 0" xyz="0.000000 -0.210000 0.000000"/>
      <geometry>
        <cylinder length="0.3" radius="0.055"/>
      </geometry>
    </visual>
  </link>
  <link name="root_left_hip_link1">
    <inertial>
      <mass value="1e-02"/>
      <inertia ixx="1e-02" ixy="0" ixz="0" iyy="1e-02" iyz="0" izz="1e-02"/>
    </inertial>
  </link>
  <joint name="root_left_hip_joint1" type="revolute">
    <origin rpy="0 0 0" xyz="0.000000 0.000000 -0.084887"/>
    <parent link="root"/>
    <child link="root_left_hip_link1"/>
    <axis xyz="1 0 0"/>
    <limit effort="200" lower="-1.5" upper="1.5" velocity="3"/>
  </joint>
  <link name="root_left_hip_link2">
    <inertial>
      <mass value="1e-02"/>
      <inertia ixx="1e-02" ixy="0" ixz="0" iyy="1e-02" iyz="0" izz="1e-02"/>
    </inertial>
    <visual>
      <geometry>
        <sphere radius="0.05"/>
      </geometry>
      <material name="orange"/>
    </visual>
  </link>
  <joint name="root_left_hip_joint2" type="revolute">
    <parent link="root_left_hip_link1"/>
    <child link="root_left_hip_link2"/>
    <axis xyz="0 1 0"/>
    <limit effort="200" lower="-1.5" upper="1.5" velocity="3"/>
  </joint>
  <joint name="root_left_hip_joint3" type="revolute">
    <parent link="root_left_hip_link2"/>
    <child link="left_hip"/>
    <axis xyz="0 0 1"/>
    <limit effort="200" lower="-1.5" upper="1.5" velocity="3"/>
  </joint>
  <link name="left_knee">
    <inertial>
      <origin rpy="0 0 0" xyz="0.000000 -0.200000 0.000000"/>
      <mass value="3.000000"/>
      <inertia ixx="0.025900000000000003" ixy="0.0" ixz="0.0" iyy="0.025900000000000003" iyz="0.0" izz="0.0037500000000000007"/>
    </inertial>
    <collision>
      <origin rpy="1.57079632679 0 0" xyz="0.000000 -0.200000 0.000000"/>
      <geometry>
        <cylinder length="0.2325" radius="0.025"/>
      </geometry>
    </collision>
    <visual>
      <origin rpy="1.57079632679 0 0" xyz="0.000000 -0.200000 0.000000"/>
      <geometry>
        <cylinder length="0.31" radius="0.05"/>
      </geometry>
    </visual>
  </link>
  <joint name="left_knee" type="revolute">
    <parent link="left_hip"/>
    <child link="left_knee"/>
    <limit effort="150.0" lower="-3.14" upper="0." velocity="0.5"/>
    <origin rpy="0 0 0" xyz="0.000000 -0.421546 0.000000"/>
    <axis xyz="0.000000 0.000000 1.000000"/>
  </joint>
  <link name="left_ankle">
    <inertial>
      <origin rpy="0 0 0" xyz="0.045 -0.00225 0.0"/>
      <mass value="1.000000"/>
      <inertia ixx="0.0009270833333333333" ixy="0.0" ixz="0.0" iyy="0.0028628333333333327" iyz="0.0" izz="0.003285749999999999"/>
    </inertial>
    <collision>
      <origin rpy="0 0 0" xyz="0.045 -0.00225 0.0"/>
      <geometry>
        <box size="0.177 0.055 0.09"/>
      </geometry>
    </collision>
    <visual>
      <origin rpy="0 0 0" xyz="0.045 -0.00225 0.0"/>
      <geometry>
        <box size="0.177 0.055 0.09"/>
      </geometry>
    </visual>
  </link>
  <link name="left_knee_left_ankle_link1">
    <inertial>
      <mass value="1e-02"/>
      <inertia ixx="1e-02" ixy="0" ixz="0" iyy="1e-02" iyz="0" izz="1e-02"/>
    </inertial>
  </link>
  <joint name="left_knee_left_ankle_joint1" type="revolute">
    <origin rpy="0 0 0" xyz="0.000000 -0.40987 0.000000"/>
    <parent link="left_knee"/>
    <child link="left_knee_left_ankle_link1"/>
    <axis xyz="1 0 0"/>
    <limit effort="90" lower="-1.2" upper="1.2" velocity="3"/>
  </joint>
  <link name="left_knee_left_ankle_link2">
    <inertial>
      <mass value="1e-02"/>
      <inertia ixx="1e-02" ixy="0" ixz="0" iyy="1e-02" iyz="0" izz="1e-02"/>
    </inertial>
    <visual>
      <geometry>
        <sphere radius="0.05"/>
      </geometry>
      <material name="orange"/>
    </visual>
  </link>
  <joint name="left_knee_left_ankle_joint2" type="revolute">
    <parent link="left_knee_left_ankle_link1"/>
    <child link="left_knee_left_ankle_link2"/>
    <axis xyz="0 1 0"/>
    <limit effort="90" lower="-1.2" upper="1.2" velocity="3"/>
  </joint>
  <joint name="left_knee_left_ankle_joint3" type="revolute">
    <parent link="left_knee_left_ankle_link2"/>
    <child link="left_ankle"/>
    <axis xyz="0 0 1"/>
    <limit effort="90" lower="-1.2" upper="1.2" velocity="3"/>
  </joint>
  <link name="left_shoulder">
    <inertial>
      <origin rpy="0 0 0" xyz="0.000000 -0.140000 0.000000"/>
      <mass value="1.500000"/>
      <inertia ixx="0.004809374999999999" ixy="0.0" ixz="0.0" iyy="0.004809374999999999" iyz="0.0" izz="0.0015187500000000001"/>
    </inertial>
    <collision>
      <origin rpy="1.57079632679 0 0" xyz="0.000000 -0.140000 0.000000"/>
      <geometry>
        <cylinder length="0.135" radius="0.0225"/>
      </geometry>
    </collision>
    <visual>
      <origin rpy="1.57079632679 0 0" xyz="0.000000 -0.140000 0.000000"/>
      <geometry>
        <cylinder length="0.18" radius="0.045"/>
      </geometry>
    </visual>
  </link>
  <link name="chest_left_shoulder_link1">
    <inertial>
      <mass value="1e-02"/>
      <inertia ixx="1e-02" ixy="0" ixz="0" iyy="1e-02" iyz="0" izz="1e-02"/>
    </inertial>
  </link>
  <joint name="chest_left_shoulder_joint1" type="revolute">
    <origin rpy="0 0 0" xyz="-0.02405 0.24350 -0.18311"/>
    <parent link="chest"/>
    <child link="chest_left_shoulder_link1"/>
    <axis xyz="1 0 0"/>
    <limit effort="100" lower="-3.14" upper="3.14" velocity="3"/>
  </joint>
  <link name="chest_left_shoulder_link2">
    <inertial>
      <mass value="1e-02"/>
      <inertia ixx="1e-02" ixy="0" ixz="0" iyy="1e-02" iyz="0" izz="1e-02"/>
    </inertial>
    <visual>
      <geometry>
        <sphere radius="0.05"/>
      </geometry>
      <material name="orange"/>
    </visual>
  </link>
  <joint name="chest_left_shoulder_joint2" type="revolute">
    <parent link="chest_left_shoulder_link1"/>
    <child link="chest_left_shoulder_link2"/>
    <axis xyz="0 1 0"/>
    <limit effort="100" lower="-3.14" upper="3.14" velocity="3"/>
  </joint>
  <joint name="chest_left_shoulder_joint3" type="revolute">
    <parent link="chest_left_shoulder_link2"/>
    <child link="left_shoulder"/>
    <axis xyz="0 0 1"/>
    <limit effort="100" lower="-3.14" upper="3.14" velocity="3"/>
  </joint>
  <link name="left_elbow">
    <inertial>
      <origin rpy="0 0 0" xyz="0.000000 -0.12 0.000000"/>
      <mass value="1.000000"/>
      <inertia ixx="0.0019187499999999999" ixy="0.0" ixz="0.0" iyy="0.0019187499999999999" iyz="0.0" izz="0.0008"/>
    </inertial>
    <collision>
      <origin rpy="1.57079632679 0 0" xyz="0.000000 -0.12 0.000000"/>
      <geometry>
        <cylinder length="0.10125" radius="0.02"/>
      </geometry>
    </collision>
    <visual>
      <origin rpy="1.57079632679 0 0" xyz="0.000000 -0.12 0.000000"/>
      <geometry>
        <cylinder length="0.135" radius="0.04"/>
      </geometry>
    </visual>
  </link>
  <joint name="left_elbow" type="revolute">
    <parent link="left_shoulder"/>
    <child link="left_elbow"/>
    <limit effort="60.0" lower="0" upper="3.14" velocity="0.5"/>
    <origin rpy="0 0 0" xyz="0.000000 -0.274788 0.000000"/>
    <axis xyz="0.000000 0.000000 1.000000"/>
  </joint>
  <link name="left_wrist">
    <inertial>
      <origin rpy="0 0 0" xyz="0.000000 0.000000 0.000000"/>
      <mass value="0.500000"/>
      <inertia ixx="0.00032" ixy="0" ixz="0" iyy="0.00032" iyz="0" izz="0.00032"/>
    </inertial>
    <collision>
      <origin rpy="0 0 0" xyz="0.000000 0.000000 0.000000"/>
      <geometry>
        <sphere radius="0.04"/>
      </geometry>
    </collision>
    <visual>
      <origin rpy="0 0 0" xyz="0.000000 0.000000 0.000000"/>
      <geometry>
        <sphere radius="0.04"/>
      </geometry>
    </visual>
  </link>
  <joint name="left_wrist_joint" type="fixed">
    <parent link="left_elbow"/>
    <child link="left_wrist"/>
    <origin rpy="0 0 0" xyz="0.000000 -0.258947 0.000000"/>
  </joint>
</robot>

